Workbook

Sheet Baca Dulu
A1: Mock-up data software udahcekbelum: NUSA HPV, CerviScan (Bio Farma), cobas HPV (Roche)
A2: Kelompok B, Track 1: Precision Diagnostics | GenoHack 2026 | Dibuat 19 Oktober 2026
A4: Tujuan | B4: Menunjukkan data apa saja yang masuk ke software dari tiap alat, dalam bentuk aslinya, lalu bagaimana software menyeragamkannya dan memakainya untuk tindak lanjut.
A5: SEMUA DATA SINTETIS | B5: Nama, ID, tanggal, dan nilai Ct dibuat oleh tim untuk demo. Bukan data pasien dan bukan hasil uji alat.
A6: Komposisi hasil | B6: Sekitar 20% sampel dibuat positif supaya alur tindak lanjut terlihat. Prevalensi nyata program sekitar 4% (Kemenkes, 2025). Jangan pakai angka di file ini sebagai estimasi pasar atau kinerja.
A7: Status NUSA HPV | B7: Alat masih rancangan konseptual dan belum tervalidasi. Kolom metilasi ditandai riset dan tidak dipakai untuk keputusan klinis.
A8: Spesifikasi CerviScan dan cobas | B8: Diambil dari dokumen publik dan materi vendor (target genotipe, kontrol internal, ambang Ct 40 untuk CerviScan). Nama kanal dan fluorofor CerviScan di sheet 3 adalah contoh. Ketersediaan Ct dari cobas belum terkonfirmasi: ditulis 'Perlu cek'.
A9: Urutan sheet | B9: 1 Kamus Data > 2 Mock NUSA > 3 Mock CerviScan (format ekspor mesin qPCR) > 4 Mock cobas > 5 Format Standar (hasil adapter, dengan rumus) > 6 Tindak Lanjut > 7 Ringkasan
A10: Warna | B10: Hijau muda = NUSA HPV; biru muda = CerviScan; oranye muda = cobas; abu-abu = berlaku untuk semua alat. Sel berisi rumus berwarna hitam; data contoh yang bisa diganti berwarna biru tua.
A12: Asumsi yang dipakai rumus
A13: Ambang Ct positif HPV | B13: 40 | C13: Ct < nilai ini = terdeteksi. Sumber: IFU CerviScan HPV-hr (ambang Ct 40).
A14: Batas Ct kontrol internal (valid jika <=) | B14: 35 | C14: Asumsi tim untuk demo. Nilai resmi per kit harus diambil dari IFU masing-masing.
A15: Jendela kirim cabang B (hari) | B15: 7 | C15: Asumsi tim untuk demo. Belum ada data stabilitas DNA cabang B.
A16: Target IVA setelah hasil positif (hari) | B16: 60 | C16: Target desain di halaman visual proposal (langkah 10).
A17: Recall hasil negatif (tahun) | B17: 10 | C17: KMK HK.01.07/MENKES/84/2026.
A18: Recall positif tipe lain, IVA normal (tahun) | B18: 3 | C18: KMK HK.01.07/MENKES/84/2026.
A19: Recall positif 16/18, IVA normal (tahun) | B19: 1 | C19: KMK HK.01.07/MENKES/84/2026.

Sheet 1 Kamus Data
A1: Tahap | B1: Variabel | C1: Arti | D1: Tipe data | E1: Satuan / nilai yang boleh | F1: NUSA HPV | G1: CerviScan (Bio Farma) | H1: cobas HPV (Roche) | I1: Sensitivitas (UU PDP) | J1: Dipakai software untuk
A2: 1 Identitas & kuesioner | B2: id_perempuan | C2: ID pseudonim perempuan | D2: Teks | E2: P-0001 dst. | F2: Ya | G2: Ya (CKG) | H2: Ya (CKG) | I2: Pribadi | J2: Menautkan semua data
A3: 1 Identitas & kuesioner | B3: nik_hash | C3: NIK yang di-hash, tidak disimpan mentah | D3: Teks | E3: Hash 64 karakter | F3: Ya | G3: Ya (CKG) | H3: Ya (CKG) | I3: Pribadi | J3: Pencocokan dengan SATUSEHAT
A4: 1 Identitas & kuesioner | B4: usia | C4: Usia saat skrining | D4: Angka | E4: Tahun, 30-69 | F4: Ya | G4: Ya | H4: Ya | I4: Pribadi | J4: Kelayakan; fitur skor risiko
A5: 1 Identitas & kuesioner | B5: riwayat_skrining | C5: Skrining sebelumnya | D5: Kategori | E5: Belum pernah / IVA / Pap / HPV DNA | F5: Ya (kuesioner) | G5: Ya (anamnesis CKG) | H5: Ya (anamnesis CKG) | I5: Spesifik (kesehatan) | J5: Fitur skor risiko; interval recall
A6: 1 Identitas & kuesioner | B6: vaksin_hpv | C6: Pernah vaksin HPV | D6: Kategori | E6: Ya / Tidak / Tidak tahu | F6: Ya (kuesioner) | G6: Perlu cek | H6: Perlu cek | I6: Spesifik (kesehatan) | J6: Fitur skor risiko
A7: 1 Identitas & kuesioner | B7: gejala_merah | C7: Perdarahan di luar haid, pascasanggama, atau pascamenopause | D7: Ya/Tidak | E7: Ya / Tidak | F7: Ya (kuesioner) | G7: Ya (anamnesis) | H7: Ya (anamnesis) | I7: Spesifik (kesehatan) | J7: Langsung arahkan ke evaluasi klinis
A8: 1 Identitas & kuesioner | B8: persetujuan | C8: Persetujuan pemeriksaan dan pemakaian data | D8: Ya/Tidak + waktu | E8: Ya / Tidak; tanggal-jam | F8: Ya (digital) | G8: Ya (formulir) | H8: Ya (formulir) | I8: Pribadi | J8: Dasar hukum pemrosesan data
A9: 2 Pengambilan sampel | B9: cara_ambil | C9: Cara pengambilan sampel | D9: Kategori | E9: Self-swab rumah / Self-swab didampingi nakes / Swab nakes | F9: Ya | G9: Ya | H9: Ya | I9: Spesifik (kesehatan) | J9: Normalisasi Ct per jenis sampel
A10: 2 Pengambilan sampel | B10: waktu_swab | C10: Waktu swab diambil | D10: Tanggal-jam | E10: YYYY-MM-DD HH:MM | F10: Ya (otomatis dari aplikasi) | G10: Manual di formulir | H10: Manual di formulir | I10: Spesifik (kesehatan) | J10: QC pra-analitik; waktu tunggu
A11: 2 Pengambilan sampel | B11: langkah_lengkap | C11: Semua langkah di aplikasi diikuti | D11: Ya/Tidak | E11: Ya / Tidak | F11: Ya | G11: Tidak | H11: Tidak | I11: Teknis | J11: QC pra-analitik
A12: 2 Pengambilan sampel | B12: inspekulo | C12: Hasil inspekulo oleh nakes | D12: Kategori | E12: Normal / Abnormal / Tidak dilakukan | F12: Tidak (tanpa nakes) | G12: Ya | H12: Ya | I12: Spesifik (kesehatan) | J12: Alur KMK 84/2026
... A36: 7 Tindak lanjut | B36: tgl_recall | C36: Tanggal pemeriksaan berikutnya | D36: Tanggal | E36: Dihitung dari kategori dan hasil IVA | F36: Ya (lewat software) | G36: Ya (lewat software) | H36: Ya (lewat software) | I36: Pribadi | J36: Pengingat; loop tertutup

Sheet 2 Mock NUSA
A1: id_perempuan | B1: barcode_A | C1: barcode_B | D1: usia | E1: riwayat_skrining | F1: vaksin_hpv | G1: gejala_merah | H1: cara_ambil | I1: waktu_swab | J1: waktu_mulai_run | K1: langkah_lengkap | L1: id_alat | M1: lot_cartridge | N1: durasi_run_menit | O1: ct_hpv16 | P1: ct_hpv18 | Q1: ct_hpv52 | R1: ct_pool_lain | S1: ct_kontrol_internal | T1: status_qc (rumus) | U1: kategori (rumus) | V1: status_cabang_B | W1: tgl_kirim_B | X1: tgl_terima_B | Y1: dalam_jendela (rumus) | Z1: genotipe_lab | AA1: metilasi (RISET) | AB1: kesesuaian_A_B
A2: P-0001 | B2: A-7100 | C2: B-7100 | D2: 59 | E2: HPV DNA | F2: Tidak tahu | G2: Ya | H2: Self-swab rumah | I2: 46300.545 | J2: 46300.562 | K2: Ya | L2: NUSA-0031 | M2: LOT-2610B | N2: 39 | S2: 22.9 | T2: =IF(AND(ISNUMBER(S2),S2<='Baca Dulu'!$B$14),"Valid","Invalid") -> Valid | U2: =IF(T2="Invalid","Invalid",IF(OR(AND(ISNUMBER(O2),O2<'Baca Dulu'!$B$13),AND(ISNUMBER(P2),P2<'Baca Dulu'!$B$13)),"Positif 16/18",IF(OR(AND(ISNUMBER(Q2),Q2<'Baca Dulu'!$B$13),AND(ISNUMBER(R2),R2<'Baca Dulu'!$B$13)),"Positif lain","Negatif"))) -> Negatif | V2: Disimpan, tidak dikirim | Y2: =IF(V2="Dikirim",IF(X2-W2<='Baca Dulu'!$B$15,"Ya","Tidak"),"")
A3: P-0002 | B3: A-7101 | C3: B-7101 | D3: 36 | E3: HPV DNA | F3: Tidak | G3: Tidak | H3: Self-swab rumah | I3: 46303.585 | J3: 46303.594 | K3: Ya | L3: NUSA-0044 | M3: LOT-2610A | N3: 49 | S3: 28 | T3: =IF(AND(ISNUMBER(S3),S3<='Baca Dulu'!$B$14),"Valid","Invalid") -> Valid | U3: =IF(T3="Invalid","Invalid",IF(OR(AND(ISNUMBER(O3),O3<'Baca Dulu'!$B$13),AND(ISNUMBER(P3),P3<'Baca Dulu'!$B$13)),"Positif 16/18",IF(OR(AND(ISNUMBER(Q3),Q3<'Baca Dulu'!$B$13),AND(ISNUMBER(R3),R3<'Baca Dulu'!$B$13)),"Positif lain","Negatif"))) -> Negatif | V3: Disimpan, tidak dikirim | Y3: =IF(V3="Dikirim",IF(X3-W3<='Baca Dulu'!$B$15,"Ya","Tidak"),"")
A4: P-0003 | B4: A-7102 | C4: B-7102 | D4: 64 | E4: Belum pernah | F4: Tidak tahu | G4: Tidak | H4: Self-swab rumah | I4: 46302.722 | J4: 46302.735 | K4: Ya | L4: NUSA-0027 | M4: LOT-2610B | N4: 39 | S4: 22.1 | T4: =IF(AND(ISNUMBER(S4),S4<='Baca Dulu'!$B$14),"Valid","Invalid") -> Valid | U4: =IF(T4="Invalid","Invalid",IF(OR(AND(ISNUMBER(O4),O4<'Baca Dulu'!$B$13),AND(ISNUMBER(P4),P4<'Baca Dulu'!$B$13)),"Positif 16/18",IF(OR(AND(ISNUMBER(Q4),Q4<'Baca Dulu'!$B$13),AND(ISNUMBER(R4),R4<'Baca Dulu'!$B$13)),"Positif lain","Negatif"))) -> Negatif | V4: Disimpan, tidak dikirim | Y4: =IF(V4="Dikirim",IF(X4-W4<='Baca Dulu'!$B$15,"Ya","Tidak"),"")
A5: P-0004 | B5: A-7103 | C5: B-7103 | D5: 49 | E5: Pap | F5: Ya | G5: Tidak | H5: Self-swab rumah | I5: 46309.631 | J5: 46309.636 | K5: Ya | L5: NUSA-0031 | M5: LOT-2610A | N5: 48 | S5: 25.9 | T5: =IF(AND(ISNUMBER(S5),S5<='Baca Dulu'!$B$14),"Valid","Invalid") -> Valid | U5: =IF(T5="Invalid","Invalid",IF(OR(AND(ISNUMBER(O5),O5<'Baca Dulu'!$B$13),AND(ISNUMBER(P5),P5<'Baca Dulu'!$B$13)),"Positif 16/18",IF(OR(AND(ISNUMBER(Q5),Q5<'Baca Dulu'!$B$13),AND(ISNUMBER(R5),R5<'Baca Dulu'!$B$13)),"Positif lain","Negatif"))) -> Negatif | V5: Disimpan, tidak dikirim | Y5: =IF(V5="Dikirim",IF(X5-W5<='Baca Dulu'!$B$15,"Ya","Tidak"),"")
A6: P-0005 | B6: A-7104 | C6: B-7104 | D6: 44 | E6: Pap | F6: Ya | G6: Tidak | H6: Self-swab rumah | I6: 46303.506 | J6: 46303.524 | K6: Ya | L6: NUSA-0012 | M6: LOT-2610B | N6: 39 | S6: 26.1 | T6: =IF(AND(ISNUMBER(S6),S6<='Baca Dulu'!$B$14),"Valid","Invalid") -> Valid | U6: =IF(T6="Invalid","Invalid",IF(OR(AND(ISNUMBER(O6),O6<'Baca Dulu'!$B$13),AND(ISNUMBER(P6),P6<'Baca Dulu'!$B$13)),"Positif 16/18",IF(OR(AND(ISNUMBER(Q6),Q6<'Baca Dulu'!$B$13),AND(ISNUMBER(R6),R6<'Baca Dulu'!$B$13)),"Positif lain","Negatif"))) -> Negatif | V6: Disimpan, tidak dikirim | Y6: =IF(V6="Dikirim",IF(X6-W6<='Baca Dulu'!$B$15,"Ya","Tidak"),"")
A7: P-0006 | B7: A-7105 | C7: B-7105 | D7: 63 | E7: Belum pernah | F7: Ya | G7: Tidak | H7: Self-swab rumah | I7: 46303.711 | J7: 46303.735 | K7: Ya | L7: NUSA-0044 | M7: LOT-2610A | N7: 46 | S7: 23 | T7: =IF(AND(ISNUMBER(S7),S7<='Baca Dulu'!$B$14),"Valid","Invalid") -> Valid | U7: =IF(T7="Invalid","Invalid",IF(OR(AND(ISNUMBER(O7),O7<'Baca Dulu'!$B$13),AND(ISNUMBER(P7),P7<'Baca Dulu'!$B$13)),"Positif 16/18",IF(OR(AND(ISNUMBER(Q7),Q7<'Baca Dulu'!$B$13),AND(ISNUMBER(R7),R7<'Baca Dulu'!$B$13)),"Positif lain","Negatif"))) -> Negatif | V7: Disimpan, tidak dikirim | Y7: =IF(V7="Dikirim",IF(X7-W7<='Baca Dulu'!$B$15,"Ya","Tidak"),"")
A8: P-0007 | B8: A-7106 | C8: B-7106 | D8: 45 | E8: Belum pernah | F8: Ya | G8: Tidak | H8: Self-swab rumah | I8: 46306.358 | J8: 46306.371 | K8: Ya | L8: NUSA-0027 | M8: LOT-2610A | N8: 40 | S8: 26.1 | T8: =IF(AND(ISNUMBER(S8),S8<='Baca Dulu'!$B$14),"Valid","Invalid") -> Valid | U8: =IF(T8="Invalid","Invalid",IF(OR(AND(ISNUMBER(O8),O8<'Baca Dulu'!$B$13),AND(ISNUMBER(P8),P8<'Baca Dulu'!$B$13)),"Positif 16/18",IF(OR(AND(ISNUMBER(Q8),Q8<'Baca Dulu'!$B$13),AND(ISNUMBER(R8),R8<'Baca Dulu'!$B$13)),"Positif lain","Negatif"))) -> Negatif | V8: Disimpan, tidak dikirim | Y8: =IF(V8="Dikirim",IF(X8-W8<='Baca Dulu'!$B$15,"Ya","Tidak"),"")
A9: P-0008 | B9: A-7107 | C9: B-7107 | D9: 55 | E9: IVA | F9: Tidak | G9: Tidak | H9: Self-swab rumah | I9: 46307.448 | J9: 46307.472 | K9: Ya | L9: NUSA-0012 | M9: LOT-2610A | N9: 51 | Q9: 35.8 | S9: 26.3 | T9: =IF(AND(ISNUMBER(S9),S9<='Baca Dulu'!$B$14),"Valid","Invalid") -> Valid | U9: =IF(T9="Invalid","Invalid",IF(OR(AND(ISNUMBER(O9),O9<'Baca Dulu'!$B$13),AND(ISNUMBER(P9),P9<'Baca Dulu'!$B$13)),"Positif 16/18",IF(OR(AND(ISNUMBER(Q9),Q9<'Baca Dulu'!$B$13),AND(ISNUMBER(R9),R9<'Baca Dulu'!$B$13)),"Positif lain","Negatif"))) -> Positif lain | V9: Dikirim | W9: 46307 | X9: 46309 | Y9: =IF(V9="Dikirim",IF(X9-W9<='Baca Dulu'!$B$15,"Ya","Tidak"),"") -> Ya | Z9: 52 | AA9: Negatif | AB9: Sesuai
A10: P-0009 | B10: A-7108 | C10: B-7108 | D10: 38 | E10: Belum pernah | F10: Tidak | G10: Tidak | H10: Self-swab rumah | I10: 46306.52 | J10: 46306.542 | K10: Ya | L10: NUSA-0012 | M10: LOT-2610B | N10: 47 | S10: 29.4 | T10: =IF(AND(ISNUMBER(S10),S10<='Baca Dulu'!$B$14),"Valid","Invalid") -> Valid | U10: =IF(T10="Invalid","Invalid",IF(OR(AND(ISNUMBER(O10),O10<'Baca Dulu'!$B$13),AND(ISNUMBER(P10),P10<'Baca Dulu'!$B$13)),"Positif 16/18",IF(OR(AND(ISNUMBER(Q10),Q10<'Baca Dulu'!$B$13),AND(ISNUMBER(R10),R10<'Baca Dulu'!$B$13)),"Positif lain","Negatif"))) -> Negatif | V10: Disimpan, tidak dikirim | Y10: =IF(V10="Dikirim",IF(X10-W10<='Baca Dulu'!$B$15,"Ya","Tidak"),"")
A11: P-0010 | B11: A-7109 | C11: B-7109 | D11: 34 | E11: Pap | F11: Tidak tahu | G11: Ya | H11: Self-swab rumah | I11: 46307.723 | J11: 46307.736 | K11: Ya | L11: NUSA-0012 | M11: LOT-2610A | N11: 48 | S11: 29.6 | T11: =IF(AND(ISNUMBER(S11),S11<='Baca Dulu'!$B$14),"Valid","Invalid") -> Valid | U11: =IF(T11="Invalid","Invalid",IF(OR(AND(ISNUMBER(O11),O11<'Baca Dulu'!$B$13),AND(ISNUMBER(P11),P11<'Baca Dulu'!$B$13)),"Positif 16/18",IF(OR(AND(ISNUMBER(Q11),Q11<'Baca Dulu'!$B$13),AND(ISNUMBER(R11),R11<'Baca Dulu'!$B$13)),"Positif lain","Negatif"))) -> Negatif | V11: Disimpan, tidak dikirim | Y11: =IF(V11="Dikirim",IF(X11-W11<='Baca Dulu'!$B$15,"Ya","Tidak"),"")
A12: P-0011 | B12: A-7110 | C12: B-7110 | D12: 35 | E12: IVA | F12: Ya | G12: Tidak | H12: Self-swab rumah | I12: 46301.687 | J12: 46301.692 | K12: Ya | L12: NUSA-0031 | M12: LOT-2610B | N12: 40 | Q12: 27.2 | S12: 24.1 | T12: =IF(AND(ISNUMBER(S12),S12<='Baca Dulu'!$B$14),"Valid","Invalid") -> Valid | U12: =IF(T12="Invalid","Invalid",IF(OR(AND(ISNUMBER(O12),O12<'Baca Dulu'!$B$13),AND(ISNUMBER(P12),P12<'Baca Dulu'!$B$13)),"Positif 16/18",IF(OR(AND(ISNUMBER(Q12),Q12<'Baca Dulu'!$B$13),AND(ISNUMBER(R12),R12<'Baca Dulu'!$B$13)),"Positif lain","Negatif"))) -> Positif lain | V12: Dikirim | W12: 46301 | X12: 46304 | Y12: =IF(V12="Dikirim",IF(X12-W12<='Baca Dulu'!$B$15,"Ya","Tidak"),"") -> Ya | Z12: 52, 59 | AA12: Negatif | AB12: Sesuai
A13: P-0012 | B13: A-7111 | C13: B-7111 | D13: 59 | E13: Belum pernah | F13: Tidak | G13: Ya | H13: Self-swab rumah | I13: 46305.64 | J13: 46305.654 | K13: Ya | L13: NUSA-0027 | M13: LOT-2610B | N13: 50 | S13: 23 | T13: =IF(AND(ISNUMBER(S13),S13<='Baca Dulu'!$B$14),"Valid","Invalid") -> Valid | U13: =IF(T13="Invalid","Invalid",IF(OR(AND(ISNUMBER(O13),O13<'Baca Dulu'!$B$13),AND(ISNUMBER(P13),P13<'Baca Dulu'!$B$13)),"Positif 16/18",IF(OR(AND(ISNUMBER(Q13),Q13<'Baca Dulu'!$B$13),AND(ISNUMBER(R13),R13<'Baca Dulu'!$B$13)),"Positif lain","Negatif"))) -> Negatif | V13: Disimpan, tidak dikirim | Y13: =IF(V13="Dikirim",IF(X13-W13<='Baca Dulu'!$B$15,"Ya","Tidak"),"")
A14: P-0013 | B14: A-7112 | C14: B-7112 | D14: 61 | E14: Belum pernah | F14: Tidak | G14: Tidak | H14: Self-swab rumah | I14: 46309.597 | J14: 46309.601 | K14: Ya | L14: NUSA-0044 | M14: LOT-2610A | N14: 48 | S14: 28 | T14: =IF(AND(ISNUMBER(S14),S14<='Baca Dulu'!$B$14),"Valid","Invalid") -> Valid | U14: =IF(T14="Invalid","Invalid",IF(OR(AND(ISNUMBER(O14),O14<'Baca Dulu'!$B$13),AND(ISNUMBER(P14),P14<'Baca Dulu'!$B$13)),"Positif 16/18",IF(OR(AND(ISNUMBER(Q14),Q14<'Baca Dulu'!$B$13),AND(ISNUMBER(R14),R14<'Baca Dulu'!$B$13)),"Positif lain","Negatif"))) -> Negatif | V14: Disimpan, tidak dikirim | Y14: =IF(V14="Dikirim",IF(X14-W14<='Baca Dulu'!$B$15,"Ya","Tidak"),"")
A15: P-0014 | B15: A-7113 | C15: B-7113 | D15: 40 | E15: Pap | F15: Tidak | G15: Tidak | H15: Self-swab rumah | I15: 46309.424 | J15: 46309.434 | K15: Ya | L15: NUSA-0027 | M15: LOT-2610B | N15: 39 | Q15: 25.7 | S15: 24.2 | T15: =IF(AND(ISNUMBER(S15),S15<='Baca Dulu'!$B$14),"Valid","Invalid") -> Valid | U15: =IF(T15="Invalid","Invalid",IF(OR(AND(ISNUMBER(O15),O15<'Baca Dulu'!$B$13),AND(ISNUMBER(P15),P15<'Baca Dulu'!$B$13)),"Positif 16/18",IF(OR(AND(ISNUMBER(Q15),Q15<'Baca Dulu'!$B$13),AND(ISNUMBER(R15),R15<'Baca Dulu'!$B$13)),"Positif lain","Negatif"))) -> Positif lain | V15: Dikirim | W15: 46309 | X15: 46313 | Y15: =IF(V15="Dikirim",IF(X15-W15<='Baca Dulu'!$B$15,"Ya","Tidak"),"") -> Ya | Z15: 52 | AA15: Belum diuji | AB15: Sesuai
A16: P-0015 | B16: A-7114 | C16: B-7114 | D16: 42 | E16: Belum pernah | F16: Tidak | G16: Tidak | H16: Self-swab rumah | I16: 46301.731 | J16: 46301.753 | K16: Ya | L16: NUSA-0027 | M16: LOT-2610A | N16: 51 | S16: 25.4 | T16: =IF(AND(ISNUMBER(S16),S16<='Baca Dulu'!$B$14),"Valid","Invalid") -> Valid | U16: =IF(T16="Invalid","Invalid",IF(OR(AND(ISNUMBER(O16),O16<'Baca Dulu'!$B$13),AND(ISNUMBER(P16),P16<'Baca Dulu'!$B$13)),"Positif 16/18",IF(OR(AND(ISNUMBER(Q16),Q16<'Baca Dulu'!$B$13),AND(ISNUMBER(R16),R16<'Baca Dulu'!$B$13)),"Positif lain","Negatif"))) -> Negatif | V16: Disimpan, tidak dikirim | Y16: =IF(V16="Dikirim",IF(X16-W16<='Baca Dulu'!$B$15,"Ya","Tidak"),"")
A17: P-0016 | B17: A-7115 | C17: B-7115 | D17: 57 | E17: IVA | F17: Tidak | G17: Tidak | H17: Self-swab rumah | I17: 46300.803 | J17: 46300.819 | K17: Ya | L17: NUSA-0012 | M17: LOT-2610B | N17: 46 | P17: 28.6 | S17: 28.3 | T17: =IF(AND(ISNUMBER(S17),S17<='Baca Dulu'!$B$14),"Valid","Invalid") -> Valid | U17: =IF(T17="Invalid","Invalid",IF(OR(AND(ISNUMBER(O17),O17<'Baca Dulu'!$B$13),AND(ISNUMBER(P17),P17<'Baca Dulu'!$B$13)),"Positif 16/18",IF(OR(AND(ISNUMBER(Q17),Q17<'Baca Dulu'!$B$13),AND(ISNUMBER(R17),R17<'Baca Dulu'!$B$13)),"Positif lain","Negatif"))) -> Positif 16/18 | V17: Dikirim | W17: 46300 | X17: 46309 | Y17: =IF(V17="Dikirim",IF(X17-W17<='Baca Dulu'!$B$15,"Ya","Tidak"),"") -> Tidak | Z17: 18 | AA17: Belum diuji | AB17: Sesuai
A18: P-0017 | B18: A-7116 | C18: B-7116 | D18: 58 | E18: IVA | F18: Tidak tahu | G18: Tidak | H18: Self-swab rumah | I18: 46308.775 | J18: 46308.79 | K18: Ya | L18: NUSA-0027 | M18: LOT-2610B | N18: 40 | S18: 28.5 | T18: =IF(AND(ISNUMBER(S18),S18<='Baca Dulu'!$B$14),"Valid","Invalid") -> Valid | U18: =IF(T18="Invalid","Invalid",IF(OR(AND(ISNUMBER(O18),O18<'Baca Dulu'!$B$13),AND(ISNUMBER(P18),P18<'Baca Dulu'!$B$13)),"Positif 16/18",IF(OR(AND(ISNUMBER(Q18),Q18<'Baca Dulu'!$B$13),AND(ISNUMBER(R18),R18<'Baca Dulu'!$B$13)),"Positif lain","Negatif"))) -> Negatif | V18: Disimpan, tidak dikirim | Y18: =IF(V18="Dikirim",IF(X18-W18<='Baca Dulu'!$B$15,"Ya","Tidak"),"")
A19: P-0018 | B19: A-7117 | C19: B-7117 | D19: 45 | E19: Belum pernah | F19: Tidak | G19: Tidak | H19: Self-swab rumah | I19: 46300.825 | J19: 46300.845 | K19: Ya | L19: NUSA-0027 | M19: LOT-2610B | N19: 44 | S19: 22.7 | T19: =IF(AND(ISNUMBER(S19),S19<='Baca Dulu'!$B$14),"Valid","Invalid") -> Valid | U19: =IF(T19="Invalid","Invalid",IF(OR(AND(ISNUMBER(O19),O19<'Baca Dulu'!$B$13),AND(ISNUMBER(P19),P19<'Baca Dulu'!$B$13)),"Positif 16/18",IF(OR(AND(ISNUMBER(Q19),Q19<'Baca Dulu'!$B$13),AND(ISNUMBER(R19),R19<'Baca Dulu'!$B$13)),"Positif lain","Negatif"))) -> Negatif | V19: Disimpan, tidak dikirim | Y19: =IF(V19="Dikirim",IF(X19-W19<='Baca Dulu'!$B$15,"Ya","Tidak"),"")
A20: P-0019 | B20: A-7118 | C20: B-7118 | D20: 60 | E20: Belum pernah | F20: Tidak | G20: Tidak | H20: Self-swab rumah | I20: 46305.754 | J20: 46305.779 | K20: Ya | L20: NUSA-0012 | M20: LOT-2610B | N20: 40 | R20: 27.9 | S20: 24.6 | T20: =IF(AND(ISNUMBER(S20),S20<='Baca Dulu'!$B$14),"Valid","Invalid") -> Valid | U20: =IF(T20="Invalid","Invalid",IF(OR(AND(ISNUMBER(O20),O20<'Baca Dulu'!$B$13),AND(ISNUMBER(P20),P20<'Baca Dulu'!$B$13)),"Positif 16/18",IF(OR(AND(ISNUMBER(Q20),Q20<'Baca Dulu'!$B$13),AND(ISNUMBER(R20),R20<'Baca Dulu'!$B$13)),"Positif lain","Negatif"))) -> Positif lain | V20: Dikirim | W20: 46306 | X20: 46309 | Y20: =IF(V20="Dikirim",IF(X20-W20<='Baca Dulu'!$B$15,"Ya","Tidak"),"") -> Ya | Z20: 45, 59 | AA20: Negatif | AB20: Sesuai
A21: P-0020 | B21: A-7119 | C21: B-7119 | D21: 55 | E21: IVA | F21: Tidak | G21: Tidak | H21: Self-swab rumah | I21: 46305.523 | J21: 46305.547 | K21: Ya | L21: NUSA-0027 | M21: LOT-2610B | N21: 40 | S21: 25.9 | T21: =IF(AND(ISNUMBER(S21),S21<='Baca Dulu'!$B$14),"Valid","Invalid") -> Valid | U21: =IF(T21="Invalid","Invalid",IF(OR(AND(ISNUMBER(O21),O21<'Baca Dulu'!$B$13),AND(ISNUMBER(P21),P21<'Baca Dulu'!$B$13)),"Positif 16/18",IF(OR(AND(ISNUMBER(Q21),Q21<'Baca Dulu'!$B$13),AND(ISNUMBER(R21),R21<'Baca Dulu'!$B$13)),"Positif lain","Negatif"))) -> Negatif | V21: Disimpan, tidak dikirim | Y21: =IF(V21="Dikirim",IF(X21-W21<='Baca Dulu'!$B$15,"Ya","Tidak"),"")
A22: P-0021 | B22: A-7120 | C22: B-7120 | D22: 32 | E22: Belum pernah | F22: Tidak | G22: Tidak | H22: Self-swab rumah | I22: 46303.367 | J22: 46303.376 | K22: Ya | L22: NUSA-0031 | M22: LOT-2610B | N22: 48 | S22: 26 | T22: =IF(AND(ISNUMBER(S22),S22<='Baca Dulu'!$B$14),"Valid","Invalid") -> Valid | U22: =IF(T22="Invalid","Invalid",IF(OR(AND(ISNUMBER(O22),O22<'Baca Dulu'!$B$13),AND(ISNUMBER(P22),P22<'Baca Dulu'!$B$13)),"Positif 16/18",IF(OR(AND(ISNUMBER(Q22),Q22<'Baca Dulu'!$B$13),AND(ISNUMBER(R22),R22<'Baca Dulu'!$B$13)),"Positif lain","Negatif"))) -> Negatif | V22: Disimpan, tidak dikirim | Y22: =IF(V22="Dikirim",IF(X22-W22<='Baca Dulu'!$B$15,"Ya","Tidak"),"")
A23: P-0022 | B23: A-7121 | C23: B-7121 | D23: 34 | E23: Belum pernah | F23: Tidak tahu | G23: Tidak | H23: Self-swab rumah | I23: 46305.684 | J23: 46305.705 | K23: Ya | L23: NUSA-0027 | M23: LOT-2610A | N23: 42 | S23: 25.8 | T23: =IF(AND(ISNUMBER(S23),S23<='Baca Dulu'!$B$14),"Valid","Invalid") -> Valid | U23: =IF(T23="Invalid","Invalid",IF(OR(AND(ISNUMBER(O23),O23<'Baca Dulu'!$B$13),AND(ISNUMBER(P23),P23<'Baca Dulu'!$B$13)),"Positif 16/18",IF(OR(AND(ISNUMBER(Q23),Q23<'Baca Dulu'!$B$13),AND(ISNUMBER(R23),R23<'Baca Dulu'!$B$13)),"Positif lain","Negatif"))) -> Negatif | V23: Disimpan, tidak dikirim | Y23: =IF(V23="Dikirim",IF(X23-W23<='Baca Dulu'!$B$15,"Ya","Tidak"),"")
A24: P-0023 | B24: A-7122 | C24: B-7122 | D24: 51 | E24: Belum pernah | F24: Tidak tahu | G24: Tidak | H24: Self-swab rumah | I24: 46302.553 | J24: 46302.579 | K24: Ya | L24: NUSA-0012 | M24: LOT-2610B | N24: 45 | S24: 30.1 | T24: =IF(AND(ISNUMBER(S24),S24<='Baca Dulu'!$B$14),"Valid","Invalid") -> Valid | U24: =IF(T24="Invalid","Invalid",IF(OR(AND(ISNUMBER(O24),O24<'Baca Dulu'!$B$13),AND(ISNUMBER(P24),P24<'Baca Dulu'!$B$13)),"Positif 16/18",IF(OR(AND(ISNUMBER(Q24),Q24<'Baca Dulu'!$B$13),AND(ISNUMBER(R24),R24<'Baca Dulu'!$B$13)),"Positif lain","Negatif"))) -> Negatif | V24: Disimpan, tidak dikirim | Y24: =IF(V24="Dikirim",IF(X24-W24<='Baca Dulu'!$B$15,"Ya","Tidak"),"")
A25: P-0024 | B25: A-7123 | C25: B-7123 | D25: 35 | E25: Belum pernah | F25: Ya | G25: Ya | H25: Self-swab rumah | I25: 46304.772 | J25: 46304.778 | K25: Tidak | L25: NUSA-0027 | M25: LOT-2610A | N25: 43 | T25: =IF(AND(ISNUMBER(S25),S25<='Baca Dulu'!$B$14),"Valid","Invalid") -> Invalid | U25: =IF(T25="Invalid","Invalid",IF(OR(AND(ISNUMBER(O25),O25<'Baca Dulu'!$B$13),AND(ISNUMBER(P25),P25<'Baca Dulu'!$B$13)),"Positif 16/18",IF(OR(AND(ISNUMBER(Q25),Q25<'Baca Dulu'!$B$13),AND(ISNUMBER(R25),R25<'Baca Dulu'!$B$13)),"Positif lain","Negatif"))) -> Invalid | V25: Disimpan, tidak dikirim | Y25: =IF(V25="Dikirim",IF(X25-W25<='Baca Dulu'!$B$15,"Ya","Tidak"),"")
A26: P-0025 | B26: A-7124 | C26: B-7124 | D26: 46 | E26: Belum pernah | F26: Tidak | G26: Tidak | H26: Self-swab rumah | I26: 46302.694 | J26: 46302.714 | K26: Ya | L26: NUSA-0027 | M26: LOT-2610B | N26: 51 | Q26: 25.7 | S26: 22.7 | T26: =IF(AND(ISNUMBER(S26),S26<='Baca Dulu'!$B$14),"Valid","Invalid") -> Valid | U26: =IF(T26="Invalid","Invalid",IF(OR(AND(ISNUMBER(O26),O26<'Baca Dulu'!$B$13),AND(ISNUMBER(P26),P26<'Baca Dulu'!$B$13)),"Positif 16/18",IF(OR(AND(ISNUMBER(Q26),Q26<'Baca Dulu'!$B$13),AND(ISNUMBER(R26),R26<'Baca Dulu'!$B$13)),"Positif lain","Negatif"))) -> Positif lain | V26: Dikirim | W26: 46304 | X26: 46305 | Y26: =IF(V26="Dikirim",IF(X26-W26<='Baca Dulu'!$B$15,"Ya","Tidak"),"") -> Ya | Z26: 52, 59 | AA26: Negatif | AB26: Sesuai
A27: P-0026 | B27: A-7125 | C27: B-7125 | D27: 57 | E27: Belum pernah | F27: Tidak tahu | G27: Tidak | H27: Self-swab rumah | I27: 46305.533 | J27: 46305.549 | K27: Tidak | L27: NUSA-0027 | M27: LOT-2610A | N27: 51 | P27: 22.9 | S27: 26 | T27: =IF(AND(ISNUMBER(S27),S27<='Baca Dulu'!$B$14),"Valid","Invalid") -> Valid | U27: =IF(T27="Invalid","Invalid",IF(OR(AND(ISNUMBER(O27),O27<'Baca Dulu'!$B$13),AND(ISNUMBER(P27),P27<'Baca Dulu'!$B$13)),"Positif 16/18",IF(OR(AND(ISNUMBER(Q27),Q27<'Baca Dulu'!$B$13),AND(ISNUMBER(R27),R27<'Baca Dulu'!$B$13)),"Positif lain","Negatif"))) -> Positif 16/18 | V27: Dikirim | W27: 46307 | X27: 46308 | Y27: =IF(V27="Dikirim",IF(X27-W27<='Baca Dulu'!$B$15,"Ya","Tidak"),"") -> Ya | Z27: 18 | AA27: Belum diuji | AB27: Sesuai
A28: P-0027 | B28: A-7126 | C28: B-7126 | D28: 47 | E28: Belum pernah | F28: Tidak | G28: Tidak | H28: Self-swab rumah | I28: 46304.553 | J28: 46304.569 | K28: Ya | L28: NUSA-0031 | M28: LOT-2610B | N28: 50 | S28: 27.8 | T28: =IF(AND(ISNUMBER(S28),S28<='Baca Dulu'!$B$14),"Valid","Invalid") -> Valid | U28: =IF(T28="Invalid","Invalid",IF(OR(AND(ISNUMBER(O28),O28<'Baca Dulu'!$B$13),AND(ISNUMBER(P28),P28<'Baca Dulu'!$B$13)),"Positif 16/18",IF(OR(AND(ISNUMBER(Q28),Q28<'Baca Dulu'!$B$13),AND(ISNUMBER(R28),R28<'Baca Dulu'!$B$13)),"Positif lain","Negatif"))) -> Negatif | V28: Disimpan, tidak dikirim | Y28: =IF(V28="Dikirim",IF(X28-W28<='Baca Dulu'!$B$15,"Ya","Tidak"),"")
A29: P-0028 | B29: A-7127 | C29: B-7127 | D29: 58 | E29: Belum pernah | F29: Ya | G29: Tidak | H29: Self-swab rumah | I29: 46300.768 | J29: 46300.784 | K29: Ya | L29: NUSA-0031 | M29: LOT-2610B | N29: 42 | S29: 22.6 | T29: =IF(AND(ISNUMBER(S29),S29<='Baca Dulu'!$B$14),"Valid","Invalid") -> Valid | U29: =IF(T29="Invalid","Invalid",IF(OR(AND(ISNUMBER(O29),O29<'Baca Dulu'!$B$13),AND(ISNUMBER(P29),P29<'Baca Dulu'!$B$13)),"Positif 16/18",IF(OR(AND(ISNUMBER(Q29),Q29<'Baca Dulu'!$B$13),AND(ISNUMBER(R29),R29<'Baca Dulu'!$B$13)),"Positif lain","Negatif"))) -> Negatif | V29: Disimpan, tidak dikirim | Y29: =IF(V29="Dikirim",IF(X29-W29<='Baca Dulu'!$B$15,"Ya","Tidak"),"")
A30: P-0029 | B30: A-7128 | C30: B-7128 | D30: 53 | E30: IVA | F30: Tidak | G30: Tidak | H30: Self-swab rumah | I30: 46300.704 | J30: 46300.717 | K30: Ya | L30: NUSA-0044 | M30: LOT-2610B | N30: 51 | S30: 27.5 | T30: =IF(AND(ISNUMBER(S30),S30<='Baca Dulu'!$B$14),"Valid","Invalid") -> Valid | U30: =IF(T30="Invalid","Invalid",IF(OR(AND(ISNUMBER(O30),O30<'Baca Dulu'!$B$13),AND(ISNUMBER(P30),P30<'Baca Dulu'!$B$13)),"Positif 16/18",IF(OR(AND(ISNUMBER(Q30),Q30<'Baca Dulu'!$B$13),AND(ISNUMBER(R30),R30<'Baca Dulu'!$B$13)),"Positif lain","Negatif"))) -> Negatif | V30: Disimpan, tidak dikirim | Y30: =IF(V30="Dikirim",IF(X30-W30<='Baca Dulu'!$B$15,"Ya","Tidak"),"")
A31: P-0030 | B31: A-7129 | C31: B-7129 | D31: 57 | E31: IVA | F31: Ya | G31: Tidak | H31: Self-swab rumah | I31: 46309.455 | J31: 46309.462 | K31: Ya | L31: NUSA-0012 | M31: LOT-2610A | N31: 43 | S31: 27.4 | T31: =IF(AND(ISNUMBER(S31),S31<='Baca Dulu'!$B$14),"Valid","Invalid") -> Valid | U31: =IF(T31="Invalid","Invalid",IF(OR(AND(ISNUMBER(O31),O31<'Baca Dulu'!$B$13),AND(ISNUMBER(P31),P31<'Baca Dulu'!$B$13)),"Positif 16/18",IF(OR(AND(ISNUMBER(Q31),Q31<'Baca Dulu'!$B$13),AND(ISNUMBER(R31),R31<'Baca Dulu'!$B$13)),"Positif lain","Negatif"))) -> Negatif | V31: Disimpan, tidak dikirim | Y31: =IF(V31="Dikirim",IF(X31-W31<='Baca Dulu'!$B$15,"Ya","Tidak"),"")
A32: P-0031 | B32: A-7130 | C32: B-7130 | D32: 39 | E32: Belum pernah | F32: Ya | G32: Tidak | H32: Self-swab rumah | I32: 46301.494 | J32: 46301.512 | K32: Ya | L32: NUSA-0044 | M32: LOT-2610B | N32: 43 | S32: 22.1 | T32: =IF(AND(ISNUMBER(S32),S32<='Baca Dulu'!$B$14),"Valid","Invalid") -> Valid | U32: =IF(T32="Invalid","Invalid",IF(OR(AND(ISNUMBER(O32),O32<'Baca Dulu'!$B$13),AND(ISNUMBER(P32),P32<'Baca Dulu'!$B$13)),"Positif 16/18",IF(OR(AND(ISNUMBER(Q32),Q32<'Baca Dulu'!$B$13),AND(ISNUMBER(R32),R32<'Baca Dulu'!$B$13)),"Positif lain","Negatif"))) -> Negatif | V32: Disimpan, tidak dikirim | Y32: =IF(V32="Dikirim",IF(X32-W32<='Baca Dulu'!$B$15,"Ya","Tidak"),"")
A33: P-0032 | B33: A-7131 | C33: B-7131 | D33: 30 | E33: Pap | F33: Tidak | G33: Tidak | H33: Self-swab rumah | I33: 46303.756 | J33: 46303.779 | K33: Ya | L33: NUSA-0027 | M33: LOT-2610B | N33: 48 | S33: 25.3 | T33: =IF(AND(ISNUMBER(S33),S33<='Baca Dulu'!$B$14),"Valid","Invalid") -> Valid | U33: =IF(T33="Invalid","Invalid",IF(OR(AND(ISNUMBER(O33),O33<'Baca Dulu'!$B$13),AND(ISNUMBER(P33),P33<'Baca Dulu'!$B$13)),"Positif 16/18",IF(OR(AND(ISNUMBER(Q33),Q33<'Baca Dulu'!$B$13),AND(ISNUMBER(R33),R33<'Baca Dulu'!$B$13)),"Positif lain","Negatif"))) -> Negatif | V33: Disimpan, tidak dikirim | Y33: =IF(V33="Dikirim",IF(X33-W33<='Baca Dulu'!$B$15,"Ya","Tidak"),"")
A34: P-0033 | B34: A-7132 | C34: B-7132 | D34: 35 | E34: Pap | F34: Tidak | G34: Tidak | H34: Self-swab rumah | I34: 46306.668 | J34: 46306.694 | K34: Ya | L34: NUSA-0031 | M34: LOT-2610B | N34: 49 | S34: 27.5 | T34: =IF(AND(ISNUMBER(S34),S34<='Baca Dulu'!$B$14),"Valid","Invalid") -> Valid | U34: =IF(T34="Invalid","Invalid",IF(OR(AND(ISNUMBER(O34),O34<'Baca Dulu'!$B$13),AND(ISNUMBER(P34),P34<'Baca Dulu'!$B$13)),"Positif 16/18",IF(OR(AND(ISNUMBER(Q34),Q34<'Baca Dulu'!$B$13),AND(ISNUMBER(R34),R34<'Baca Dulu'!$B$13)),"Positif lain","Negatif"))) -> Negatif | V34: Disimpan, tidak dikirim | Y34: =IF(V34="Dikirim",IF(X34-W34<='Baca Dulu'!$B$15,"Ya","Tidak"),"")
A35: P-0034 | B35: A-7133 | C35: B-7133 | D35: 45 | E35: Belum pernah | F35: Tidak | G35: Tidak | H35: Self-swab rumah | I35: 46309.549 | J35: 46309.571 | K35: Ya | L35: NUSA-0044 | M35: LOT-2610A | N35: 50 | S35: 30.1 | T35: =IF(AND(ISNUMBER(S35),S35<='Baca Dulu'!$B$14),"Valid","Invalid") -> Valid | U35: =IF(T35="Invalid","Invalid",IF(OR(AND(ISNUMBER(O35),O35<'Baca Dulu'!$B$13),AND(ISNUMBER(P35),P35<'Baca Dulu'!$B$13)),"Positif 16/18",IF(OR(AND(ISNUMBER(Q35),Q35<'Baca Dulu'!$B$13),AND(ISNUMBER(R35),R35<'Baca Dulu'!$B$13)),"Positif lain","Negatif"))) -> Negatif | V35: Disimpan, tidak dikirim | Y35: =IF(V35="Dikirim",IF(X35-W35<='Baca Dulu'!$B$15,"Ya","Tidak"),"")
A36: P-0035 | B36: A-7134 | C36: B-7134 | D36: 59 | E36: HPV DNA | F36: Tidak | G36: Tidak | H36: Self-swab rumah | I36: 46309.644 | J36: 46309.65 | K36: Ya | L36: NUSA-0044 | M36: LOT-2610A | N36: 48 | P36: 30.4 | S36: 29.9 | T36: =IF(AND(ISNUMBER(S36),S36<='Baca Dulu'!$B$14),"Valid","Invalid") -> Valid | U36: =IF(T36="Invalid","Invalid",IF(OR(AND(ISNUMBER(O36),O36<'Baca Dulu'!$B$13),AND(ISNUMBER(P36),P36<'Baca Dulu'!$B$13)),"Positif 16/18",IF(OR(AND(ISNUMBER(Q36),Q36<'Baca Dulu'!$B$13),AND(ISNUMBER(R36),R36<'Baca Dulu'!$B$13)),"Positif lain","Negatif"))) -> Positif 16/18 | V36: Dikirim | W36: 46309 | X36: 46312 | Y36: =IF(V36="Dikirim",IF(X36-W36<='Baca Dulu'!$B$15,"Ya","Tidak"),"") -> Ya | Z36: 18 | AA36: Negatif | AB36: Sesuai
A37: P-0036 | B37: A-7135 | C37: B-7135 | D37: 30 | E37: IVA | F37: Tidak tahu | G37: Tidak | H37: Self-swab rumah | I37: 46308.446 | J37: 46308.465 | K37: Ya | L37: NUSA-0031 | M37: LOT-2610B | N37: 50 | S37: 23.8 | T37: =IF(AND(ISNUMBER(S37),S37<='Baca Dulu'!$B$14),"Valid","Invalid") -> Valid | U37: =IF(T37="Invalid","Invalid",IF(OR(AND(ISNUMBER(O37),O37<'Baca Dulu'!$B$13),AND(ISNUMBER(P37),P37<'Baca Dulu'!$B$13)),"Positif 16/18",IF(OR(AND(ISNUMBER(Q37),Q37<'Baca Dulu'!$B$13),AND(ISNUMBER(R37),R37<'Baca Dulu'!$B$13)),"Positif lain","Negatif"))) -> Negatif | V37: Disimpan, tidak dikirim | Y37: =IF(V37="Dikirim",IF(X37-W37<='Baca Dulu'!$B$15,"Ya","Tidak"),"")
A38: P-0037 | B38: A-7136 | C38: B-7136 | D38: 63 | E38: Pap | F38: Ya | G38: Tidak | H38: Self-swab rumah | I38: 46303.505 | J38: 46303.517 | K38: Tidak | L38: NUSA-0031 | M38: LOT-2610A | N38: 46 | S38: 36.2 | T38: =IF(AND(ISNUMBER(S38),S38<='Baca Dulu'!$B$14),"Valid","Invalid") -> Invalid | U38: =IF(T38="Invalid","Invalid",IF(OR(AND(ISNUMBER(O38),O38<'Baca Dulu'!$B$13),AND(ISNUMBER(P38),P38<'Baca Dulu'!$B$13)),"Positif 16/18",IF(OR(AND(ISNUMBER(Q38),Q38<'Baca Dulu'!$B$13),AND(ISNUMBER(R38),R38<'Baca Dulu'!$B$13)),"Positif lain","Negatif"))) -> Invalid | V38: Disimpan, tidak dikirim | Y38: =IF(V38="Dikirim",IF(X38-W38<='Baca Dulu'!$B$15,"Ya","Tidak"),"")
A39: P-0038 | B39: A-7137 | C39: B-7137 | D39: 31 | E39: Belum pernah | F39: Tidak | G39: Tidak | H39: Self-swab rumah | I39: 46301.729 | J39: 46301.742 | K39: Ya | L39: NUSA-0044 | M39: LOT-2610B | N39: 44 | S39: 27.6 | T39: =IF(AND(ISNUMBER(S39),S39<='Baca Dulu'!$B$14),"Valid","Invalid") -> Valid | U39: =IF(T39="Invalid","Invalid",IF(OR(AND(ISNUMBER(O39),O39<'Baca Dulu'!$B$13),AND(ISNUMBER(P39),P39<'Baca Dulu'!$B$13)),"Positif 16/18",IF(OR(AND(ISNUMBER(Q39),Q39<'Baca Dulu'!$B$13),AND(ISNUMBER(R39),R39<'Baca Dulu'!$B$13)),"Positif lain","Negatif"))) -> Negatif | V39: Disimpan, tidak dikirim | Y39: =IF(V39="Dikirim",IF(X39-W39<='Baca Dulu'!$B$15,"Ya","Tidak"),"")
A40: P-0039 | B40: A-7138 | C40: B-7138 | D40: 33 | E40: Belum pernah | F40: Tidak | G40: Tidak | H40: Self-swab rumah | I40: 46300.549 | J40: 46300.556 | K40: Ya | L40: NUSA-0044 | M40: LOT-2610B | N40: 46 | S40: 23.8 | T40: =IF(AND(ISNUMBER(S40),S40<='Baca Dulu'!$B$14),"Valid","Invalid") -> Valid | U40: =IF(T40="Invalid","Invalid",IF(OR(AND(ISNUMBER(O40),O40<'Baca Dulu'!$B$13),AND(ISNUMBER(P40),P40<'Baca Dulu'!$B$13)),"Positif 16/18",IF(OR(AND(ISNUMBER(Q40),Q40<'Baca Dulu'!$B$13),AND(ISNUMBER(R40),R40<'Baca Dulu'!$B$13)),"Positif lain","Negatif"))) -> Negatif | V40: Disimpan, tidak dikirim | Y40: =IF(V40="Dikirim",IF(X40-W40<='Baca Dulu'!$B$15,"Ya","Tidak"),"")
...

Sheet 3 Mock CerviScan
A1: Contoh bentuk ekspor mesin qPCR terbuka (mis. CFX/ABI) untuk CerviScan HPV-hr: satu baris per sumur per target. Nama kanal di kolom D adalah contoh, bukan spesifikasi resmi.
A2: Well | B2: Sample | C2: Target | D2: Kanal (contoh) | E2: Cq | F2: id_perempuan | G2: lab | H2: tgl_run
A3: A01 | B3: CS-26-3400 | C3: HPV16 | D3: Kanal 1 | E3: N/A | F3: P-0061 | G3: Labkesda DKI | H3: 46306
A4: A01 | B4: CS-26-3400 | C4: HPV18 | D4: Kanal 2 | E4: N/A | F4: P-0061 | G4: Labkesda DKI | H4: 46306
A5: A01 | B5: CS-26-3400 | C5: HPV52 | D5: Kanal 3 | E5: N/A | F5: P-0061 | G5: Labkesda DKI | H5: 46306
A6: A01 | B6: CS-26-3400 | C6: HR lain (11 tipe) | D6: Kanal 4 | E6: N/A | F6: P-0061 | G6: Labkesda DKI | H6: 46306
A7: A01 | B7: CS-26-3400 | C7: Beta-globin (IC) | D7: Kanal 5 | E7: 24.9 | F7: P-0061 | G7: Labkesda DKI | H7: 46306
A8: B01 | B8: CS-26-3401 | C8: HPV16 | D8: Kanal 1 | E8: N/A | F8: P-0062 | G8: Labkesda DKI | H8: 46306
A9: B01 | B9: CS-26-3401 | C9: HPV18 | D9: Kanal 2 | E9: N/A | F9: P-0062 | G9: Labkesda DKI | H9: 46306
A10: B01 | B10: CS-26-3401 | C10: HPV52 | D10: Kanal 3 | E10: N/A | F10: P-0062 | G10: Labkesda DKI | H10: 46306
A11: B01 | B11: CS-26-3401 | C11: HR lain (11 tipe) | D11: Kanal 4 | E11: N/A | F11: P-0062 | G11: Labkesda DKI | H11: 46306
A12: B01 | B12: CS-26-3401 | C12: Beta-globin (IC) | D12: Kanal 5 | E12: 26.9 | F12: P-0062 | G12: Labkesda DKI | H12: 46306
A13: C01 | B13: CS-26-3402 | C13: HPV16 | D13: Kanal 1 | E13: N/A | F13: P-0063 | G13: Labkesda DKI | H13: 46304
A14: C01 | B14: CS-26-3402 | C14: HPV18 | D14: Kanal 2 | E14: N/A | F14: P-0063 | G14: Labkesda DKI | H14: 46304
A15: C01 | B15: CS-26-3402 | C15: HPV52 | D15: Kanal 3 | E15: N/A | F15: P-0063 | G15: Labkesda DKI | H15: 46304
A16: C01 | B16: CS-26-3402 | C16: HR lain (11 tipe) | D16: Kanal 4 | E16: N/A | F16: P-0063 | G16: Labkesda DKI | H16: 46304
A17: C01 | B17: CS-26-3402 | C17: Beta-globin (IC) | D17: Kanal 5 | E17: 25.9 | F17: P-0063 | G17: Labkesda DKI | H17: 46304
A18: D01 | B18: CS-26-3403 | C18: HPV16 | D18: Kanal 1 | E18: N/A | F18: P-0064 | G18: Labkesda DKI | H18: 46310
A19: D01 | B19: CS-26-3403 | C19: HPV18 | D19: Kanal 2 | E19: N/A | F19: P-0064 | G19: Labkesda DKI | H19: 46310
A20: D01 | B20: CS-26-3403 | C20: HPV52 | D20: Kanal 3 | E20: N/A | F20: P-0064 | G20: Labkesda DKI | H20: 46310
A21: D01 | B21: CS-26-3403 | C21: HR lain (11 tipe) | D21: Kanal 4 | E21: N/A | F21: P-0064 | G21: Labkesda DKI | H21: 46310
A22: D01 | B22: CS-26-3403 | C22: Beta-globin (IC) | D22: Kanal 5 | E22: 29.5 | F22: P-0064 | G22: Labkesda DKI | H22: 46310
A23: E01 | B23: CS-26-3404 | C23: HPV16 | D23: Kanal 1 | E23: N/A | F23: P-0065 | G23: Labkesda DKI | H23: 46305
A24: E01 | B24: CS-26-3404 | C24: HPV18 | D24: Kanal 2 | E24: N/A | F24: P-0065 | G24: Labkesda DKI | H24: 46305
A25: E01 | B25: CS-26-3404 | C25: HPV52 | D25: Kanal 3 | E25: N/A | F25: P-0065 | G25: Labkesda DKI | H25: 46305
A26: E01 | B26: CS-26-3404 | C26: HR lain (11 tipe) | D26: Kanal 4 | E26: N/A | F26: P-0065 | G26: Labkesda DKI | H26: 46305
A27: E01 | B27: CS-26-3404 | C27: Beta-globin (IC) | D27: Kanal 5 | E27: 29.6 | F27: P-0065 | G27: Labkesda DKI | H27: 46305
A28: F01 | B28: CS-26-3405 | C28: HPV16 | D28: Kanal 1 | E28: N/A | F28: P-0066 | G28: Lab RSUD Pasar Minggu | H28: 46313
A29: F01 | B29: CS-26-3405 | C29: HPV18 | D29: Kanal 2 | E29: N/A | F29: P-0066 | G29: Lab RSUD Pasar Minggu | H29: 46313
A30: F01 | B30: CS-26-3405 | C30: HPV52 | D30: Kanal 3 | E30: N/A | F30: P-0066 | G30: Lab RSUD Pasar Minggu | H30: 46313
A31: F01 | B31: CS-26-3405 | C31: HR lain (11 tipe) | D31: Kanal 4 | E31: N/A | F31: P-0066 | G31: Lab RSUD Pasar Minggu | H31: 46313
A32: F01 | B32: CS-26-3405 | C32: Beta-globin (IC) | D32: Kanal 5 | E32: 29.8 | F32: P-0066 | G32: Lab RSUD Pasar Minggu | H32: 46313
A33: G01 | B33: CS-26-3406 | C33: HPV16 | D33: Kanal 1 | E33: N/A | F33: P-0067 | G33: Lab RSUD Pasar Minggu | H33: 46306
A34: G01 | B34: CS-26-3406 | C34: HPV18 | D34: Kanal 2 | E34: N/A | F34: P-0067 | G34: Lab RSUD Pasar Minggu | H34: 46306
A35: G01 | B35: CS-26-3406 | C35: HPV52 | D35: Kanal 3 | E35: N/A | F35: P-0067 | G35: Lab RSUD Pasar Minggu | H35: 46306
A36: G01 | B36: CS-26-3406 | C36: HR lain (11 tipe) | D36: Kanal 4 | E36: N/A | F36: P-0067 | G36: Lab RSUD Pasar Minggu | H36: 46306
A37: G01 | B37: CS-26-3406 | C37: Beta-globin (IC) | D37: Kanal 5 | E37: 28.1 | F37: P-0067 | G37: Lab RSUD Pasar Minggu | H37: 46306
A38: H01 | B38: CS-26-3407 | C38: HPV16 | D38: Kanal 1 | E38: N/A | F38: P-0068 | G38: Labkesda DKI | H38: 46311
A39: H01 | B39: CS-26-3407 | C39: HPV18 | D39: Kanal 2 | E39: N/A | F39: P-0068 | G39: Labkesda DKI | H39: 46311
A40: H01 | B40: CS-26-3407 | C40: HPV52 | D40: Kanal 3 | E40: N/A | F40: P-0068 | G40: Labkesda DKI | H40: 46311
...

Sheet 4 Mock cobas
A1: Contoh bentuk laporan hasil cobas HPV: kategori per target. Kolom Ct ditulis 'Perlu cek' karena ketersediaannya untuk pengguna belum terkonfirmasi.
A2: Sample ID | B2: id_perempuan | C2: HPV16 | D2: HPV18 | E2: Other HR (12 tipe) | F2: Validity | G2: Ct (semua kanal) | H2: lab | I2: tgl_run
A3: CB-26-8800 | B3: P-0121 | C3: NEG | D3: NEG | E3: NEG | F3: Valid | G3: Perlu cek | H3: Labkesda Surabaya (hub) | I3: 46313
A4: CB-26-8801 | B4: P-0122 | C4: NEG | D4: NEG | E4: NEG | F4: Valid | G4: Perlu cek | H4: Lab hub DKI (contoh) | I4: 46306
A5: CB-26-8802 | B5: P-0123 | C5: NEG | D5: NEG | E5: NEG | F5: Valid | G5: Perlu cek | H5: Lab hub DKI (contoh) | I5: 46305
A6: CB-26-8803 | B6: P-0124 | C6: POS | D6: NEG | E6: NEG | F6: Valid | G6: Perlu cek | H6: Labkesda Surabaya (hub) | I6: 46304
A7: CB-26-8804 | B7: P-0125 | C7: NEG | D7: NEG | E7: NEG | F7: Valid | G7: Perlu cek | H7: Lab hub DKI (contoh) | I7: 46306
A8: CB-26-8805 | B8: P-0126 | C8: NEG | D8: NEG | E8: NEG | F8: Valid | G8: Perlu cek | H8: Lab hub DKI (contoh) | I8: 46304
A9: CB-26-8806 | B9: P-0127 | C9: NEG | D9: NEG | E9: NEG | F9: Valid | G9: Perlu cek | H9: Labkesda Surabaya (hub) | I9: 46313
A10: CB-26-8807 | B10: P-0128 | C10: NEG | D10: NEG | E10: POS | F10: Valid | G10: Perlu cek | H10: Lab hub DKI (contoh) | I10: 46313
A11: CB-26-8808 | B11: P-0129 | C11: Invalid | D11: Invalid | E11: Invalid | F11: Invalid | G11: Perlu cek | H11: Lab hub DKI (contoh) | I11: 46312
A12: CB-26-8809 | B12: P-0130 | C12: NEG | D12: NEG | E12: NEG | F12: Valid | G12: Perlu cek | H12: Labkesda Surabaya (hub) | I12: 46309
A13: CB-26-8810 | B13: P-0131 | C13: NEG | D13: NEG | E13: NEG | F13: Valid | G13: Perlu cek | H13: Lab hub DKI (contoh) | I13: 46310
A14: CB-26-8811 | B14: P-0132 | C14: NEG | D14: NEG | E14: NEG | F14: Valid | G14: Perlu cek | H14: Lab hub DKI (contoh) | I14: 46315
... A62: CB-26-8859 | B62: P-0180 | C62: NEG | D62: NEG | E62: NEG | F62: Valid | G62: Perlu cek | H62: Lab hub DKI (contoh) | I62: 46311

Sheet 5 Format Standar
A1: Hasil adapter software: semua sampel dari tiga alat dalam satu format. Semua kolom berwarna hitam adalah rumus yang menarik data dari sheet 2, 3, dan 4.
A2: sumber_alat | B2: id_sampel | C2: id_perempuan | D2: ct_hpv16 | E2: ct_hpv18 | F2: ct_hpv52 | G2: ct_pool_lain | H2: ct_kontrol_internal | I2: hasil_16 | J2: hasil_18 | K2: hasil_lain (52+pool) | L2: valid | M2: kategori_kemenkes | N2: delta_ct | O2: tgl_hasil | P2: kelengkapan_data
A3: NUSA HPV | B3: ='2 Mock NUSA'!B2 -> A-7100 | C3: ='2 Mock NUSA'!A2 -> P-0001 | D3: =IF(ISNUMBER('2 Mock NUSA'!O2),'2 Mock NUSA'!O2,"") | E3: =IF(ISNUMBER('2 Mock NUSA'!P2),'2 Mock NUSA'!P2,"") | F3: =IF(ISNUMBER('2 Mock NUSA'!Q2),'2 Mock NUSA'!Q2,"") | G3: =IF(ISNUMBER('2 Mock NUSA'!R2),'2 Mock NUSA'!R2,"") | H3: =IF(ISNUMBER('2 Mock NUSA'!S2),'2 Mock NUSA'!S2,"") -> 22.9 | I3: =IF(L3="Tidak","Invalid",IF(AND(ISNUMBER(D3),D3<'Baca Dulu'!$B$13),"Positif","Negatif")) -> Negatif | J3: =IF(L3="Tidak","Invalid",IF(AND(ISNUMBER(E3),E3<'Baca Dulu'!$B$13),"Positif","Negatif")) -> Negatif | K3: =IF(L3="Tidak","Invalid",IF(OR(AND(ISNUMBER(F3),F3<'Baca Dulu'!$B$13),AND(ISNUMBER(G3),G3<'Baca Dulu'!$B$13)),"Positif","Negatif")) -> Negatif | L3: =IF(AND(ISNUMBER(H3),H3<='Baca Dulu'!$B$14),"Ya","Tidak") -> Ya | M3: =IF(L3="Tidak","Invalid",IF(OR(I3="Positif",J3="Positif"),"Positif 16/18",IF(K3="Positif","Positif lain","Negatif"))) -> Negatif | N3: =IF(AND(L3="Ya",COUNT(D3:G3)>0),MIN(D3:G3)-H3,"") | O3: =INT('2 Mock NUSA'!J2) -> 46300 | P3: Lengkap: Ct + kurva + pra-analitik + cabang B
A4: NUSA HPV | B4: ='2 Mock NUSA'!B3 -> A-7101 | C4: ='2 Mock NUSA'!A3 -> P-0002 | D4: =IF(ISNUMBER('2 Mock NUSA'!O3),'2 Mock NUSA'!O3,"") | E4: =IF(ISNUMBER('2 Mock NUSA'!P3),'2 Mock NUSA'!P3,"") | F4: =IF(ISNUMBER('2 Mock NUSA'!Q3),'2 Mock NUSA'!Q3,"") | G4: =IF(ISNUMBER('2 Mock NUSA'!R3),'2 Mock NUSA'!R3,"") | H4: =IF(ISNUMBER('2 Mock NUSA'!S3),'2 Mock NUSA'!S3,"") -> 28 | I4: =IF(L4="Tidak","Invalid",IF(AND(ISNUMBER(D4),D4<'Baca Dulu'!$B$13),"Positif","Negatif")) -> Negatif | J4: =IF(L4="Tidak","Invalid",IF(AND(ISNUMBER(E4),E4<'Baca Dulu'!$B$13),"Positif","Negatif")) -> Negatif | K4: =IF(L4="Tidak","Invalid",IF(OR(AND(ISNUMBER(F4),F4<'Baca Dulu'!$B$13),AND(ISNUMBER(G4),G4<'Baca Dulu'!$B$13)),"Positif","Negatif")) -> Negatif | L4: =IF(AND(ISNUMBER(H4),H4<='Baca Dulu'!$B$14),"Ya","Tidak") -> Ya | M4: =IF(L4="Tidak","Invalid",IF(OR(I4="Positif",J4="Positif"),"Positif 16/18",IF(K4="Positif","Positif lain","Negatif"))) -> Negatif | N4: =IF(AND(L4="Ya",COUNT(D4:G4)>0),MIN(D4:G4)-H4,"") | O4: =INT('2 Mock NUSA'!J3) -> 46303 | P4: Lengkap: Ct + kurva + pra-analitik + cabang B
A5: NUSA HPV | B5: ='2 Mock NUSA'!B4 -> A-7102 | C5: ='2 Mock NUSA'!A4 -> P-0003 | D5: =IF(ISNUMBER('2 Mock NUSA'!O4),'2 Mock NUSA'!O4,"") | E5: =IF(ISNUMBER('2 Mock NUSA'!P4),'2 Mock NUSA'!P4,"") | F5: =IF(ISNUMBER('2 Mock NUSA'!Q4),'2 Mock NUSA'!Q4,"") | G5: =IF(ISNUMBER('2 Mock NUSA'!R4),'2 Mock NUSA'!R4,"") | H5: =IF(ISNUMBER('2 Mock NUSA'!S4),'2 Mock NUSA'!S4,"") -> 22.1 | I5: =IF(L5="Tidak","Invalid",IF(AND(ISNUMBER(D5),D5<'Baca Dulu'!$B$13),"Positif","Negatif")) -> Negatif | J5: =IF(L5="Tidak","Invalid",IF(AND(ISNUMBER(E5),E5<'Baca Dulu'!$B$13),"Positif","Negatif")) -> Negatif | K5: =IF(L5="Tidak","Invalid",IF(OR(AND(ISNUMBER(F5),F5<'Baca Dulu'!$B$13),AND(ISNUMBER(G5),G5<'Baca Dulu'!$B$13)),"Positif","Negatif")) -> Negatif | L5: =IF(AND(ISNUMBER(H5),H5<='Baca Dulu'!$B$14),"Ya","Tidak") -> Ya | M5: =IF(L5="Tidak","Invalid",IF(OR(I5="Positif",J5="Positif"),"Positif 16/18",IF(K5="Positif","Positif lain","Negatif"))) -> Negatif | N5: =IF(AND(L5="Ya",COUNT(D5:G5)>0),MIN(D5:G5)-H5,"") | O5: =INT('2 Mock NUSA'!J4) -> 46302 | P5: Lengkap: Ct + kurva + pra-analitik + cabang B
A6: NUSA HPV | B6: ='2 Mock NUSA'!B5 -> A-7103 | C6: ='2 Mock NUSA'!A5 -> P-0004 | D6: =IF(ISNUMBER('2 Mock NUSA'!O5),'2 Mock NUSA'!O5,"") | E6: =IF(ISNUMBER('2 Mock NUSA'!P5),'2 Mock NUSA'!P5,"") | F6: =IF(ISNUMBER('2 Mock NUSA'!Q5),'2 Mock NUSA'!Q5,"") | G6: =IF(ISNUMBER('2 Mock NUSA'!R5),'2 Mock NUSA'!R5,"") | H6: =IF(ISNUMBER('2 Mock NUSA'!S5),'2 Mock NUSA'!S5,"") -> 25.9 | I6: =IF(L6="Tidak","Invalid",IF(AND(ISNUMBER(D6),D6<'Baca Dulu'!$B$13),"Positif","Negatif")) -> Negatif | J6: =IF(L6="Tidak","Invalid",IF(AND(ISNUMBER(E6),E6<'Baca Dulu'!$B$13),"Positif","Negatif")) -> Negatif | K6: =IF(L6="Tidak","Invalid",IF(OR(AND(ISNUMBER(F6),F6<'Baca Dulu'!$B$13),AND(ISNUMBER(G6),G6<'Baca Dulu'!$B$13)),"Positif","Negatif")) -> Negatif | L6: =IF(AND(ISNUMBER(H6),H6<='Baca Dulu'!$B$14),"Ya","Tidak") -> Ya | M6: =IF(L6="Tidak","Invalid",IF(OR(I6="Positif",J6="Positif"),"Positif 16/18",IF(K6="Positif","Positif lain","Negatif"))) -> Negatif | N6: =IF(AND(L6="Ya",COUNT(D6:G6)>0),MIN(D6:G6)-H6,"") | O6: =INT('2 Mock NUSA'!J5) -> 46309 | P6: Lengkap: Ct + kurva + pra-analitik + cabang B
A7: NUSA HPV | B7: ='2 Mock NUSA'!B6 -> A-7104 | C7: ='2 Mock NUSA'!A6 -> P-0005 | D7: =IF(ISNUMBER('2 Mock NUSA'!O6),'2 Mock NUSA'!O6,"") | E7: =IF(ISNUMBER('2 Mock NUSA'!P6),'2 Mock NUSA'!P6,"") | F7: =IF(ISNUMBER('2 Mock NUSA'!Q6),'2 Mock NUSA'!Q6,"") | G7: =IF(ISNUMBER('2 Mock NUSA'!R6),'2 Mock NUSA'!R6,"") | H7: =IF(ISNUMBER('2 Mock NUSA'!S6),'2 Mock NUSA'!S6,"") -> 26.1 | I7: =IF(L7="Tidak","Invalid",IF(AND(ISNUMBER(D7),D7<'Baca Dulu'!$B$13),"Positif","Negatif")) -> Negatif | J7: =IF(L7="Tidak","Invalid",IF(AND(ISNUMBER(E7),E7<'Baca Dulu'!$B$13),"Positif","Negatif")) -> Negatif | K7: =IF(L7="Tidak","Invalid",IF(OR(AND(ISNUMBER(F7),F7<'Baca Dulu'!$B$13),AND(ISNUMBER(G7),G7<'Baca Dulu'!$B$13)),"Positif","Negatif")) -> Negatif | L7: =IF(AND(ISNUMBER(H7),H7<='Baca Dulu'!$B$14),"Ya","Tidak") -> Ya | M7: =IF(L7="Tidak","Invalid",IF(OR(I7="Positif",J7="Positif"),"Positif 16/18",IF(K7="Positif","Positif lain","Negatif"))) -> Negatif | N7: =IF(AND(L7="Ya",COUNT(D7:G7)>0),MIN(D7:G7)-H7,"") | O7: =INT('2 Mock NUSA'!J6) -> 46303 | P7: Lengkap: Ct + kurva + pra-analitik + cabang B
A8: NUSA HPV | B8: ='2 Mock NUSA'!B7 -> A-7105 | C8: ='2 Mock NUSA'!A7 -> P-0006 | D8: =IF(ISNUMBER('2 Mock NUSA'!O7),'2 Mock NUSA'!O7,"") | E8: =IF(ISNUMBER('2 Mock NUSA'!P7),'2 Mock NUSA'!P7,"") | F8: =IF(ISNUMBER('2 Mock NUSA'!Q7),'2 Mock NUSA'!Q7,"") | G8: =IF(ISNUMBER('2 Mock NUSA'!R7),'2 Mock NUSA'!R7,"") | H8: =IF(ISNUMBER('2 Mock NUSA'!S7),'2 Mock NUSA'!S7,"") -> 23 | I8: =IF(L8="Tidak","Invalid",IF(AND(ISNUMBER(D8),D8<'Baca Dulu'!$B$13),"Positif","Negatif")) -> Negatif | J8: =IF(L8="Tidak","Invalid",IF(AND(ISNUMBER(E8),E8<'Baca Dulu'!$B$13),"Positif","Negatif")) -> Negatif | K8: =IF(L8="Tidak","Invalid",IF(OR(AND(ISNUMBER(F8),F8<'Baca Dulu'!$B$13),AND(ISNUMBER(G8),G8<'Baca Dulu'!$B$13)),"Positif","Negatif")) -> Negatif | L8: =IF(AND(ISNUMBER(H8),H8<='Baca Dulu'!$B$14),"Ya","Tidak") -> Ya | M8: =IF(L8="Tidak","Invalid",IF(OR(I8="Positif",J8="Positif"),"Positif 16/18",IF(K8="Positif","Positif lain","Negatif"))) -> Negatif | N8: =IF(AND(L8="Ya",COUNT(D8:G8)>0),MIN(D8:G8)-H8,"") | O8: =INT('2 Mock NUSA'!J7) -> 46303 | P8: Lengkap: Ct + kurva + pra-analitik + cabang B
A9: NUSA HPV | B9: ='2 Mock NUSA'!B8 -> A-7106 | C9: ='2 Mock NUSA'!A8 -> P-0007 | D9: =IF(ISNUMBER('2 Mock NUSA'!O8),'2 Mock NUSA'!O8,"") | E9: =IF(ISNUMBER('2 Mock NUSA'!P8),'2 Mock NUSA'!P8,"") | F9: =IF(ISNUMBER('2 Mock NUSA'!Q8),'2 Mock NUSA'!Q8,"") | G9: =IF(ISNUMBER('2 Mock NUSA'!R8),'2 Mock NUSA'!R8,"") | H9: =IF(ISNUMBER('2 Mock NUSA'!S8),'2 Mock NUSA'!S8,"") -> 26.1 | I9: =IF(L9="Tidak","Invalid",IF(AND(ISNUMBER(D9),D9<'Baca Dulu'!$B$13),"Positif","Negatif")) -> Negatif | J9: =IF(L9="Tidak","Invalid",IF(AND(ISNUMBER(E9),E9<'Baca Dulu'!$B$13),"Positif","Negatif")) -> Negatif | K9: =IF(L9="Tidak","Invalid",IF(OR(AND(ISNUMBER(F9),F9<'Baca Dulu'!$B$13),AND(ISNUMBER(G9),G9<'Baca Dulu'!$B$13)),"Positif","Negatif")) -> Negatif | L9: =IF(AND(ISNUMBER(H9),H9<='Baca Dulu'!$B$14),"Ya","Tidak") -> Ya | M9: =IF(L9="Tidak","Invalid",IF(OR(I9="Positif",J9="Positif"),"Positif 16/18",IF(K9="Positif","Positif lain","Negatif"))) -> Negatif | N9: =IF(AND(L9="Ya",COUNT(D9:G9)>0),MIN(D9:G9)-H9,"") | O9: =INT('2 Mock NUSA'!J8) -> 46306 | P9: Lengkap: Ct + kurva + pra-analitik + cabang B
A10: NUSA HPV | B10: ='2 Mock NUSA'!B9 -> A-7107 | C10: ='2 Mock NUSA'!A9 -> P-0008 | D10: =IF(ISNUMBER('2 Mock NUSA'!O9),'2 Mock NUSA'!O9,"") | E10: =IF(ISNUMBER('2 Mock NUSA'!P9),'2 Mock NUSA'!P9,"") | F10: =IF(ISNUMBER('2 Mock NUSA'!Q9),'2 Mock NUSA'!Q9,"") -> 35.8 | G10: =IF(ISNUMBER('2 Mock NUSA'!R9),'2 Mock NUSA'!R9,"") | H10: =IF(ISNUMBER('2 Mock NUSA'!S9),'2 Mock NUSA'!S9,"") -> 26.3 | I10: =IF(L10="Tidak","Invalid",IF(AND(ISNUMBER(D10),D10<'Baca Dulu'!$B$13),"Positif","Negatif")) -> Negatif | J10: =IF(L10="Tidak","Invalid",IF(AND(ISNUMBER(E10),E10<'Baca Dulu'!$B$13),"Positif","Negatif")) -> Negatif | K10: =IF(L10="Tidak","Invalid",IF(OR(AND(ISNUMBER(F10),F10<'Baca Dulu'!$B$13),AND(ISNUMBER(G10),G10<'Baca Dulu'!$B$13)),"Positif","Negatif")) -> Positif | L10: =IF(AND(ISNUMBER(H10),H10<='Baca Dulu'!$B$14),"Ya","Tidak") -> Ya | M10: =IF(L10="Tidak","Invalid",IF(OR(I10="Positif",J10="Positif"),"Positif 16/18",IF(K10="Positif","Positif lain","Negatif"))) -> Positif lain | N10: =IF(AND(L10="Ya",COUNT(D10:G10)>0),MIN(D10:G10)-H10,"") -> 9.5 | O10: =INT('2 Mock NUSA'!J9) -> 46307 | P10: Lengkap: Ct + kurva + pra-analitik + cabang B
A11: NUSA HPV | B11: ='2 Mock NUSA'!B10 -> A-7108 | C11: ='2 Mock NUSA'!A10 -> P-0009 | D11: =IF(ISNUMBER('2 Mock NUSA'!O10),'2 Mock NUSA'!O10,"") | E11: =IF(ISNUMBER('2 Mock NUSA'!P10),'2 Mock NUSA'!P10,"") | F11: =IF(ISNUMBER('2 Mock NUSA'!Q10),'2 Mock NUSA'!Q10,"") | G11: =IF(ISNUMBER('2 Mock NUSA'!R10),'2 Mock NUSA'!R10,"") | H11: =IF(ISNUMBER('2 Mock NUSA'!S10),'2 Mock NUSA'!S10,"") -> 29.4 | I11: =IF(L11="Tidak","Invalid",IF(AND(ISNUMBER(D11),D11<'Baca Dulu'!$B$13),"Positif","Negatif")) -> Negatif | J11: =IF(L11="Tidak","Invalid",IF(AND(ISNUMBER(E11),E11<'Baca Dulu'!$B$13),"Positif","Negatif")) -> Negatif | K11: =IF(L11="Tidak","Invalid",IF(OR(AND(ISNUMBER(F11),F11<'Baca Dulu'!$B$13),AND(ISNUMBER(G11),G11<'Baca Dulu'!$B$13)),"Positif","Negatif")) -> Negatif | L11: =IF(AND(ISNUMBER(H11),H11<='Baca Dulu'!$B$14),"Ya","Tidak") -> Ya | M11: =IF(L11="Tidak","Invalid",IF(OR(I11="Positif",J11="Positif"),"Positif 16/18",IF(K11="Positif","Positif lain","Negatif"))) -> Negatif | N11: =IF(AND(L11="Ya",COUNT(D11:G11)>0),MIN(D11:G11)-H11,"") | O11: =INT('2 Mock NUSA'!J10) -> 46306 | P11: Lengkap: Ct + kurva + pra-analitik + cabang B
A12: NUSA HPV | B12: ='2 Mock NUSA'!B11 -> A-7109 | C12: ='2 Mock NUSA'!A11 -> P-0010 | D12: =IF(ISNUMBER('2 Mock NUSA'!O11),'2 Mock NUSA'!O11,"") | E12: =IF(ISNUMBER('2 Mock NUSA'!P11),'2 Mock NUSA'!P11,"") | F12: =IF(ISNUMBER('2 Mock NUSA'!Q11),'2 Mock NUSA'!Q11,"") | G12: =IF(ISNUMBER('2 Mock NUSA'!R11),'2 Mock NUSA'!R11,"") | H12: =IF(ISNUMBER('2 Mock NUSA'!S11),'2 Mock NUSA'!S11,"") -> 29.6 | I12: =IF(L12="Tidak","Invalid",IF(AND(ISNUMBER(D12),D12<'Baca Dulu'!$B$13),"Positif","Negatif")) -> Negatif | J12: =IF(L12="Tidak","Invalid",IF(AND(ISNUMBER(E12),E12<'Baca Dulu'!$B$13),"Positif","Negatif")) -> Negatif | K12: =IF(L12="Tidak","Invalid",IF(OR(AND(ISNUMBER(F12),F12<'Baca Dulu'!$B$13),AND(ISNUMBER(G12),G12<'Baca Dulu'!$B$13)),"Positif","Negatif")) -> Negatif | L12: =IF(AND(ISNUMBER(H12),H12<='Baca Dulu'!$B$14),"Ya","Tidak") -> Ya | M12: =IF(L12="Tidak","Invalid",IF(OR(I12="Positif",J12="Positif"),"Positif 16/18",IF(K12="Positif","Positif lain","Negatif"))) -> Negatif | N12: =IF(AND(L12="Ya",COUNT(D12:G12)>0),MIN(D12:G12)-H12,"") | O12: =INT('2 Mock NUSA'!J11) -> 46307 | P12: Lengkap: Ct + kurva + pra-analitik + cabang B
A13: NUSA HPV | B13: ='2 Mock NUSA'!B12 -> A-7110 | C13: ='2 Mock NUSA'!A12 -> P-0011 | D13: =IF(ISNUMBER('2 Mock NUSA'!O12),'2 Mock NUSA'!O12,"") | E13: =IF(ISNUMBER('2 Mock NUSA'!P12),'2 Mock NUSA'!P12,"") | F13: =IF(ISNUMBER('2 Mock NUSA'!Q12),'2 Mock NUSA'!Q12,"") -> 27.2 | G13: =IF(ISNUMBER('2 Mock NUSA'!R12),'2 Mock NUSA'!R12,"") | H13: =IF(ISNUMBER('2 Mock NUSA'!S12),'2 Mock NUSA'!S12,"") -> 24.1 | I13: =IF(L13="Tidak","Invalid",IF(AND(ISNUMBER(D13),D13<'Baca Dulu'!$B$13),"Positif","Negatif")) -> Negatif | J13: =IF(L13="Tidak","Invalid",IF(AND(ISNUMBER(E13),E13<'Baca Dulu'!$B$13),"Positif","Negatif")) -> Negatif | K13: =IF(L13="Tidak","Invalid",IF(OR(AND(ISNUMBER(F13),F13<'Baca Dulu'!$B$13),AND(ISNUMBER(G13),G13<'Baca Dulu'!$B$13)),"Positif","Negatif")) -> Positif | L13: =IF(AND(ISNUMBER(H13),H13<='Baca Dulu'!$B$14),"Ya","Tidak") -> Ya | M13: =IF(L13="Tidak","Invalid",IF(OR(I13="Positif",J13="Positif"),"Positif 16/18",IF(K13="Positif","Positif lain","Negatif"))) -> Positif lain | N13: =IF(AND(L13="Ya",COUNT(D13:G13)>0),MIN(D13:G13)-H13,"") -> 3.1 | O13: =INT('2 Mock NUSA'!J12) -> 46301 | P13: Lengkap: Ct + kurva + pra-analitik + cabang B
A14: NUSA HPV | B14: ='2 Mock NUSA'!B13 -> A-7111 | C14: ='2 Mock NUSA'!A13 -> P-0012 | D14: =IF(ISNUMBER('2 Mock NUSA'!O13),'2 Mock NUSA'!O13,"") | E14: =IF(ISNUMBER('2 Mock NUSA'!P13),'2 Mock NUSA'!P13,"") | F14: =IF(ISNUMBER('2 Mock NUSA'!Q13),'2 Mock NUSA'!Q13,"") | G14: =IF(ISNUMBER('2 Mock NUSA'!R13),'2 Mock NUSA'!R13,"") | H14: =IF(ISNUMBER('2 Mock NUSA'!S13),'2 Mock NUSA'!S13,"") -> 23 | I14: =IF(L14="Tidak","Invalid",IF(AND(ISNUMBER(D14),D14<'Baca Dulu'!$B$13),"Positif","Negatif")) -> Negatif | J14: =IF(L14="Tidak","Invalid",IF(AND(ISNUMBER(E14),E14<'Baca Dulu'!$B$13),"Positif","Negatif")) -> Negatif | K14: =IF(L14="Tidak","Invalid",IF(OR(AND(ISNUMBER(F14),F14<'Baca Dulu'!$B$13),AND(ISNUMBER(G14),G14<'Baca Dulu'!$B$13)),"Positif","Negatif")) -> Negatif | L14: =IF(AND(ISNUMBER(H14),H14<='Baca Dulu'!$B$14),"Ya","Tidak") -> Ya | M14: =IF(L14="Tidak","Invalid",IF(OR(I14="Positif",J14="Positif"),"Positif 16/18",IF(K14="Positif","Positif lain","Negatif"))) -> Negatif | N14: =IF(AND(L14="Ya",COUNT(D14:G14)>0),MIN(D14:G14)-H14,"") | O14: =INT('2 Mock NUSA'!J13) -> 46305 | P14: Lengkap: Ct + kurva + pra-analitik + cabang B
... A62: NUSA HPV | B62: ='2 Mock NUSA'!B61 -> A-7159 | C62: ='2 Mock NUSA'!A61 -> P-0060 | D62: =IF(ISNUMBER('2 Mock NUSA'!O61),'2 Mock NUSA'!O61,"") | E62: =IF(ISNUMBER('2 Mock NUSA'!P61),'2 Mock NUSA'!P61,"") | F62: =IF(ISNUMBER('2 Mock NUSA'!Q61),'2 Mock NUSA'!Q61,"") | G62: =IF(ISNUMBER('2 Mock NUSA'!R61),'2 Mock NUSA'!R61,"") | H62: =IF(ISNUMBER('2 Mock NUSA'!S61),'2 Mock NUSA'!S61,"") -> 25.5 | I62: =IF(L62="Tidak","Invalid",IF(AND(ISNUMBER(D62),D62<'Baca Dulu'!$B$13),"Positif","Negatif")) -> Negatif | J62: =IF(L62="Tidak","Invalid",IF(AND(ISNUMBER(E62),E62<'Baca Dulu'!$B$13),"Positif","Negatif")) -> Negatif | K62: =IF(L62="Tidak","Invalid",IF(OR(AND(ISNUMBER(F62),F62<'Baca Dulu'!$B$13),AND(ISNUMBER(G62),G62<'Baca Dulu'!$B$13)),"Positif","Negatif")) -> Negatif | L62: =IF(AND(ISNUMBER(H62),H62<='Baca Dulu'!$B$14),"Ya","Tidak") -> Ya | M62: =IF(L62="Tidak","Invalid",IF(OR(I62="Positif",J62="Positif"),"Positif 16/18",IF(K62="Positif","Positif lain","Negatif"))) -> Negatif | N62: =IF(AND(L62="Ya",COUNT(D62:G62)>0),MIN(D62:G62)-H62,"") | O62: =INT('2 Mock NUSA'!J61) -> 46308 | P62: Lengkap: Ct + kurva + pra-analitik + cabang B
A63: CerviScan | B63: CS-26-3400 | C63: =INDEX('3 Mock CerviScan'!$F$3:$F$302,MATCH(B63,'3 Mock CerviScan'!$B$3:$B$302,0)) -> P-0061 | D63: =IFERROR(AVERAGEIFS('3 Mock CerviScan'!$E$3:$E$302,'3 Mock CerviScan'!$B$3:$B$302,$B63,'3 Mock CerviScan'!$C$3:$C$302,"HPV16"),"") | E63: =IFERROR(AVERAGEIFS('3 Mock CerviScan'!$E$3:$E$302,'3 Mock CerviScan'!$B$3:$B$302,$B63,'3 Mock CerviScan'!$C$3:$C$302,"HPV18"),"") | F63: =IFERROR(AVERAGEIFS('3 Mock CerviScan'!$E$3:$E$302,'3 Mock CerviScan'!$B$3:$B$302,$B63,'3 Mock CerviScan'!$C$3:$C$302,"HPV52"),"") | G63: =IFERROR(AVERAGEIFS('3 Mock CerviScan'!$E$3:$E$302,'3 Mock CerviScan'!$B$3:$B$302,$B63,'3 Mock CerviScan'!$C$3:$C$302,"HR lain (11 tipe)"),"") | H63: =IFERROR(AVERAGEIFS('3 Mock CerviScan'!$E$3:$E$302,'3 Mock CerviScan'!$B$3:$B$302,$B63,'3 Mock CerviScan'!$C$3:$C$302,"Beta-globin (IC)"),"") -> 24.9 | I63: =IF(L63="Tidak","Invalid",IF(AND(ISNUMBER(D63),D63<'Baca Dulu'!$B$13),"Positif","Negatif")) -> Negatif | J63: =IF(L63="Tidak","Invalid",IF(AND(ISNUMBER(E63),E63<'Baca Dulu'!$B$13),"Positif","Negatif")) -> Negatif | K63: =IF(L63="Tidak","Invalid",IF(OR(AND(ISNUMBER(F63),F63<'Baca Dulu'!$B$13),AND(ISNUMBER(G63),G63<'Baca Dulu'!$B$13)),"Positif","Negatif")) -> Negatif | L63: =IF(AND(ISNUMBER(H63),H63<='Baca Dulu'!$B$14),"Ya","Tidak") -> Ya | M63: =IF(L63="Tidak","Invalid",IF(OR(I63="Positif",J63="Positif"),"Positif 16/18",IF(K63="Positif","Positif lain","Negatif"))) -> Negatif | N63: =IF(AND(L63="Ya",COUNT(D63:G63)>0),MIN(D63:G63)-H63,"") | O63: =INDEX('3 Mock CerviScan'!$H$3:$H$302,MATCH(B63,'3 Mock CerviScan'!$B$3:$B$302,0)) -> 46306 | P63: Ct per kanal + kontrol internal
A64: CerviScan | B64: CS-26-3401 | C64: =INDEX('3 Mock CerviScan'!$F$3:$F$302,MATCH(B64,'3 Mock CerviScan'!$B$3:$B$302,0)) -> P-0062 | D64: =IFERROR(AVERAGEIFS('3 Mock CerviScan'!$E$3:$E$302,'3 Mock CerviScan'!$B$3:$B$302,$B64,'3 Mock CerviScan'!$C$3:$C$302,"HPV16"),"") | E64: =IFERROR(AVERAGEIFS('3 Mock CerviScan'!$E$3:$E$302,'3 Mock CerviScan'!$B$3:$B$302,$B64,'3 Mock CerviScan'!$C$3:$C$302,"HPV18"),"") | F64: =IFERROR(AVERAGEIFS('3 Mock CerviScan'!$E$3:$E$302,'3 Mock CerviScan'!$B$3:$B$302,$B64,'3 Mock CerviScan'!$C$3:$C$302,"HPV52"),"") | G64: =IFERROR(AVERAGEIFS('3 Mock CerviScan'!$E$3:$E$302,'3 Mock CerviScan'!$B$3:$B$302,$B64,'3 Mock CerviScan'!$C$3:$C$302,"HR lain (11 tipe)"),"") | H64: =IFERROR(AVERAGEIFS('3 Mock CerviScan'!$E$3:$E$302,'3 Mock CerviScan'!$B$3:$B$302,$B64,'3 Mock CerviScan'!$C$3:$C$302,"Beta-globin (IC)"),"") -> 26.9 | I64: =IF(L64="Tidak","Invalid",IF(AND(ISNUMBER(D64),D64<'Baca Dulu'!$B$13),"Positif","Negatif")) -> Negatif | J64: =IF(L64="Tidak","Invalid",IF(AND(ISNUMBER(E64),E64<'Baca Dulu'!$B$13),"Positif","Negatif")) -> Negatif | K64: =IF(L64="Tidak","Invalid",IF(OR(AND(ISNUMBER(F64),F64<'Baca Dulu'!$B$13),AND(ISNUMBER(G64),G64<'Baca Dulu'!$B$13)),"Positif","Negatif")) -> Negatif | L64: =IF(AND(ISNUMBER(H64),H64<='Baca Dulu'!$B$14),"Ya","Tidak") -> Ya | M64: =IF(L64="Tidak","Invalid",IF(OR(I64="Positif",J64="Positif"),"Positif 16/18",IF(K64="Positif","Positif lain","Negatif"))) -> Negatif | N64: =IF(AND(L64="Ya",COUNT(D64:G64)>0),MIN(D64:G64)-H64,"") | O64: =INDEX('3 Mock CerviScan'!$H$3:$H$302,MATCH(B64,'3 Mock CerviScan'!$B$3:$B$302,0)) -> 46306 | P64: Ct per kanal + kontrol internal
A65: CerviScan | B65: CS-26-3402 | C65: =INDEX('3 Mock CerviScan'!$F$3:$F$302,MATCH(B65,'3 Mock CerviScan'!$B$3:$B$302,0)) -> P-0063 | D65: =IFERROR(AVERAGEIFS('3 Mock CerviScan'!$E$3:$E$302,'3 Mock CerviScan'!$B$3:$B$302,$B65,'3 Mock CerviScan'!$C$3:$C$302,"HPV16"),"") | E65: =IFERROR(AVERAGEIFS('3 Mock CerviScan'!$E$3:$E$302,'3 Mock CerviScan'!$B$3:$B$302,$B65,'3 Mock CerviScan'!$C$3:$C$302,"HPV18"),"") | F65: =IFERROR(AVERAGEIFS('3 Mock CerviScan'!$E$3:$E$302,'3 Mock CerviScan'!$B$3:$B$302,$B65,'3 Mock CerviScan'!$C$3:$C$302,"HPV52"),"") | G65: =IFERROR(AVERAGEIFS('3 Mock CerviScan'!$E$3:$E$302,'3 Mock CerviScan'!$B$3:$B$302,$B65,'3 Mock CerviScan'!$C$3:$C$302,"HR lain (11 tipe)"),"") | H65: =IFERROR(AVERAGEIFS('3 Mock CerviScan'!$E$3:$E$302,'3 Mock CerviScan'!$B$3:$B$302,$B65,'3 Mock CerviScan'!$C$3:$C$302,"Beta-globin (IC)"),"") -> 25.9 | I65: =IF(L65="Tidak","Invalid",IF(AND(ISNUMBER(D65),D65<'Baca Dulu'!$B$13),"Positif","Negatif")) -> Negatif | J65: =IF(L65="Tidak","Invalid",IF(AND(ISNUMBER(E65),E65<'Baca Dulu'!$B$13),"Positif","Negatif")) -> Negatif | K65: =IF(L65="Tidak","Invalid",IF(OR(AND(ISNUMBER(F65),F65<'Baca Dulu'!$B$13),AND(ISNUMBER(G65),G65<'Baca Dulu'!$B$13)),"Positif","Negatif")) -> Negatif | L65: =IF(AND(ISNUMBER(H65),H65<='Baca Dulu'!$B$14),"Ya","Tidak") -> Ya | M65: =IF(L65="Tidak","Invalid",IF(OR(I65="Positif",J65="Positif"),"Positif 16/18",IF(K65="Positif","Positif lain","Negatif"))) -> Negatif | N65: =IF(AND(L65="Ya",COUNT(D65:G65)>0),MIN(D65:G65)-H65,"") | O65: =INDEX('3 Mock CerviScan'!$H$3:$H$302,MATCH(B65,'3 Mock CerviScan'!$B$3:$B$302,0)) -> 46304 | P65: Ct per kanal + kontrol internal
